INFO       - 2023-12-19 20:03:13,466 - client          : logging in using static token
INFO       - 2023-12-19 20:03:14,612 - gateway         : Shard ID None has sent the IDENTIFY payload.
INFO       - 2023-12-19 20:03:15,131 - gateway         : Shard ID None has connected to Gateway: ["gateway-prd-us-east1-b-325x",{"micros":163314,"calls":["id_created",{"micros":1348,"calls":[]},"session_lookup_time",{"micros":2760,"calls":[]},"session_lookup_finished",{"micros":20,"calls":[]},"discord-sessions-prd-2-241",{"micros":158402,"calls":["start_session",{"micros":132182,"calls":["discord-api-dc69f8484-8gt46",{"micros":106865,"calls":["get_user",{"micros":19802},"get_guilds",{"micros":6590},"send_scheduled_deletion_message",{"micros":10},"guild_join_requests",{"micros":1},"authorized_ip_coro",{"micros":12}]}]},"starting_guild_connect",{"micros":68,"calls":[]},"presence_started",{"micros":2207,"calls":[]},"guilds_started",{"micros":179,"calls":[]},"guilds_connect",{"micros":2,"calls":[]},"presence_connect",{"micros":23715,"calls":[]},"connect_finished",{"micros":23721,"calls":[]},"build_ready",{"micros":40,"calls":[]},"clean_ready",{"micros":1,"calls":[]},"optimize_ready",{"micros":1,"calls":[]},"split_ready",{"micros":0,"calls":[]}]}]}] (Session ID: e51fc580bc949ec6c627aef27dd55abb).
INFO       - 2023-12-19 20:03:25,703 - voice_client    : Connecting to voice...
INFO       - 2023-12-19 20:03:25,703 - voice_client    : Starting voice handshake... (connection attempt 1)
INFO       - 2023-12-19 20:03:26,276 - voice_client    : Voice handshake complete. Endpoint found india5924.discord.media
INFO       - 2023-12-19 20:03:26,755 - gateway         : selected the voice protocol for use (xsalsa20_poly1305_lite)
INFO       - 2023-12-19 20:03:26,809 - gateway         : received secret key for voice connection
INFO       - 2023-12-19 20:03:41,357 - player          : Preparing to terminate ffmpeg process 18412.
INFO       - 2023-12-19 20:03:41,357 - player          : ffmpeg process 18412 has not terminated. Waiting to terminate...
INFO       - 2023-12-19 20:03:41,366 - player          : ffmpeg process 18412 should have terminated with a return code of 1.
INFO       - 2023-12-19 20:08:04,491 - player          : Preparing to terminate ffmpeg process 17008.
INFO       - 2023-12-19 20:08:04,492 - player          : ffmpeg process 17008 successfully terminated with return code of 0.
ERROR      - 2023-12-19 20:42:33,395 - voice_client    : Disconnected from voice... Reconnecting in 0.31s.
Traceback (most recent call last):
  File "D:\disscord_bots\music\.venv\Lib\site-packages\discord\voice_client.py", line 467, in poll_voice_ws
    await self.ws.poll_event()
  File "D:\disscord_bots\music\.venv\Lib\site-packages\discord\gateway.py", line 956, in poll_event
    raise ConnectionClosed(self.ws, shard_id=None, code=self._close_code)
discord.errors.ConnectionClosed: Shard ID None WebSocket closed with 1006
INFO       - 2023-12-19 20:42:33,748 - voice_client    : The voice handshake is being terminated for Channel ID 1185958109823381597 (Guild ID 1185958109353615501)
INFO       - 2023-12-19 20:42:33,749 - voice_client    : Connecting to voice...
INFO       - 2023-12-19 20:42:33,749 - voice_client    : Starting voice handshake... (connection attempt 2)
INFO       - 2023-12-19 20:42:45,550 - gateway         : Timed out receiving packet. Attempting a reconnect.
INFO       - 2023-12-19 20:42:45,552 - client          : Got a request to RESUME the websocket.
ERROR      - 2023-12-19 20:42:45,559 - client          : Attempting a reconnect in 1.39s
Traceback (most recent call last):
  File "D:\disscord_bots\music\.venv\Lib\site-packages\aiohttp\connector.py", line 1173, in _create_direct_connection
    hosts = await asyncio.shield(host_resolved)
            ^^^^^^^^^^^^^^^^^^^^^^^^^^^^^^^^^^^
  File "D:\disscord_bots\music\.venv\Lib\site-packages\aiohttp\connector.py", line 884, in _resolve_host
    addrs = await self._resolver.resolve(host, port, family=self._family)
            ^^^^^^^^^^^^^^^^^^^^^^^^^^^^^^^^^^^^^^^^^^^^^^^^^^^^^^^^^^^^^
  File "D:\disscord_bots\music\.venv\Lib\site-packages\aiohttp\resolver.py", line 33, in resolve
    infos = await self._loop.getaddrinfo(
            ^^^^^^^^^^^^^^^^^^^^^^^^^^^^^
  File "C:\Users\Lenovo\AppData\Local\Programs\Python\Python311\Lib\asyncio\base_events.py", line 867, in getaddrinfo
    return await self.run_in_executor(
           ^^^^^^^^^^^^^^^^^^^^^^^^^^^
  File "C:\Users\Lenovo\AppData\Local\Programs\Python\Python311\Lib\concurrent\futures\thread.py", line 58, in run
    result = self.fn(*self.args, **self.kwargs)
             ^^^^^^^^^^^^^^^^^^^^^^^^^^^^^^^^^^
  File "C:\Users\Lenovo\AppData\Local\Programs\Python\Python311\Lib\socket.py", line 962, in getaddrinfo
    for res in _socket.getaddrinfo(host, port, family, type, proto, flags):
               ^^^^^^^^^^^^^^^^^^^^^^^^^^^^^^^^^^^^^^^^^^^^^^^^^^^^^^^^^^^
socket.gaierror: [Errno 11001] getaddrinfo failed

The above exception was the direct cause of the following exception:

Traceback (most recent call last):
  File "D:\disscord_bots\music\.venv\Lib\site-packages\discord\client.py", line 597, in connect
    self.ws = await asyncio.wait_for(coro, timeout=60.0)
              ^^^^^^^^^^^^^^^^^^^^^^^^^^^^^^^^^^^^^^^^^^
  File "C:\Users\Lenovo\AppData\Local\Programs\Python\Python311\Lib\asyncio\tasks.py", line 489, in wait_for
    return fut.result()
           ^^^^^^^^^^^^
  File "D:\disscord_bots\music\.venv\Lib\site-packages\discord\gateway.py", line 337, in from_client
    gateway = gateway or await client.http.get_gateway()
                         ^^^^^^^^^^^^^^^^^^^^^^^^^^^^^^^
  File "D:\disscord_bots\music\.venv\Lib\site-packages\discord\http.py", line 2905, in get_gateway
    data = await self.request(Route("GET", "/gateway"))
           ^^^^^^^^^^^^^^^^^^^^^^^^^^^^^^^^^^^^^^^^^^^^
  File "D:\disscord_bots\music\.venv\Lib\site-packages\discord\http.py", line 283, in request
    async with self.__session.request(
  File "D:\disscord_bots\music\.venv\Lib\site-packages\aiohttp\client.py", line 1187, in __aenter__
    self._resp = await self._coro
                 ^^^^^^^^^^^^^^^^
  File "D:\disscord_bots\music\.venv\Lib\site-packages\aiohttp\client.py", line 574, in _request
    conn = await self._connector.connect(
           ^^^^^^^^^^^^^^^^^^^^^^^^^^^^^^
  File "D:\disscord_bots\music\.venv\Lib\site-packages\aiohttp\connector.py", line 544, in connect
    proto = await self._create_connection(req, traces, timeout)
            ^^^^^^^^^^^^^^^^^^^^^^^^^^^^^^^^^^^^^^^^^^^^^^^^^^^
  File "D:\disscord_bots\music\.venv\Lib\site-packages\aiohttp\connector.py", line 911, in _create_connection
    _, proto = await self._create_direct_connection(req, traces, timeout)
               ^^^^^^^^^^^^^^^^^^^^^^^^^^^^^^^^^^^^^^^^^^^^^^^^^^^^^^^^^^
  File "D:\disscord_bots\music\.venv\Lib\site-packages\aiohttp\connector.py", line 1187, in _create_direct_connection
    raise ClientConnectorError(req.connection_key, exc) from exc
aiohttp.client_exceptions.ClientConnectorError: Cannot connect to host discord.com:443 ssl:default [getaddrinfo failed]
ERROR      - 2023-12-19 20:42:47,172 - client          : Attempting a reconnect in 2.41s
Traceback (most recent call last):
  File "D:\disscord_bots\music\.venv\Lib\site-packages\aiohttp\connector.py", line 1173, in _create_direct_connection
    hosts = await asyncio.shield(host_resolved)
            ^^^^^^^^^^^^^^^^^^^^^^^^^^^^^^^^^^^
  File "D:\disscord_bots\music\.venv\Lib\site-packages\aiohttp\connector.py", line 884, in _resolve_host
    addrs = await self._resolver.resolve(host, port, family=self._family)
            ^^^^^^^^^^^^^^^^^^^^^^^^^^^^^^^^^^^^^^^^^^^^^^^^^^^^^^^^^^^^^
  File "D:\disscord_bots\music\.venv\Lib\site-packages\aiohttp\resolver.py", line 33, in resolve
    infos = await self._loop.getaddrinfo(
            ^^^^^^^^^^^^^^^^^^^^^^^^^^^^^
  File "C:\Users\Lenovo\AppData\Local\Programs\Python\Python311\Lib\asyncio\base_events.py", line 867, in getaddrinfo
    return await self.run_in_executor(
           ^^^^^^^^^^^^^^^^^^^^^^^^^^^
  File "C:\Users\Lenovo\AppData\Local\Programs\Python\Python311\Lib\concurrent\futures\thread.py", line 58, in run
    result = self.fn(*self.args, **self.kwargs)
             ^^^^^^^^^^^^^^^^^^^^^^^^^^^^^^^^^^
  File "C:\Users\Lenovo\AppData\Local\Programs\Python\Python311\Lib\socket.py", line 962, in getaddrinfo
    for res in _socket.getaddrinfo(host, port, family, type, proto, flags):
               ^^^^^^^^^^^^^^^^^^^^^^^^^^^^^^^^^^^^^^^^^^^^^^^^^^^^^^^^^^^
socket.gaierror: [Errno 11001] getaddrinfo failed

The above exception was the direct cause of the following exception:

Traceback (most recent call last):
  File "D:\disscord_bots\music\.venv\Lib\site-packages\discord\client.py", line 597, in connect
    self.ws = await asyncio.wait_for(coro, timeout=60.0)
              ^^^^^^^^^^^^^^^^^^^^^^^^^^^^^^^^^^^^^^^^^^
  File "C:\Users\Lenovo\AppData\Local\Programs\Python\Python311\Lib\asyncio\tasks.py", line 489, in wait_for
    return fut.result()
           ^^^^^^^^^^^^
  File "D:\disscord_bots\music\.venv\Lib\site-packages\discord\gateway.py", line 337, in from_client
    gateway = gateway or await client.http.get_gateway()
                         ^^^^^^^^^^^^^^^^^^^^^^^^^^^^^^^
  File "D:\disscord_bots\music\.venv\Lib\site-packages\discord\http.py", line 2905, in get_gateway
    data = await self.request(Route("GET", "/gateway"))
           ^^^^^^^^^^^^^^^^^^^^^^^^^^^^^^^^^^^^^^^^^^^^
  File "D:\disscord_bots\music\.venv\Lib\site-packages\discord\http.py", line 283, in request
    async with self.__session.request(
  File "D:\disscord_bots\music\.venv\Lib\site-packages\aiohttp\client.py", line 1187, in __aenter__
    self._resp = await self._coro
                 ^^^^^^^^^^^^^^^^
  File "D:\disscord_bots\music\.venv\Lib\site-packages\aiohttp\client.py", line 574, in _request
    conn = await self._connector.connect(
           ^^^^^^^^^^^^^^^^^^^^^^^^^^^^^^
  File "D:\disscord_bots\music\.venv\Lib\site-packages\aiohttp\connector.py", line 544, in connect
    proto = await self._create_connection(req, traces, timeout)
            ^^^^^^^^^^^^^^^^^^^^^^^^^^^^^^^^^^^^^^^^^^^^^^^^^^^
  File "D:\disscord_bots\music\.venv\Lib\site-packages\aiohttp\connector.py", line 911, in _create_connection
    _, proto = await self._create_direct_connection(req, traces, timeout)
               ^^^^^^^^^^^^^^^^^^^^^^^^^^^^^^^^^^^^^^^^^^^^^^^^^^^^^^^^^^
  File "D:\disscord_bots\music\.venv\Lib\site-packages\aiohttp\connector.py", line 1187, in _create_direct_connection
    raise ClientConnectorError(req.connection_key, exc) from exc
aiohttp.client_exceptions.ClientConnectorError: Cannot connect to host discord.com:443 ssl:default [getaddrinfo failed]
ERROR      - 2023-12-19 20:42:49,614 - client          : Attempting a reconnect in 6.44s
Traceback (most recent call last):
  File "D:\disscord_bots\music\.venv\Lib\site-packages\aiohttp\connector.py", line 1173, in _create_direct_connection
    hosts = await asyncio.shield(host_resolved)
            ^^^^^^^^^^^^^^^^^^^^^^^^^^^^^^^^^^^
  File "D:\disscord_bots\music\.venv\Lib\site-packages\aiohttp\connector.py", line 884, in _resolve_host
    addrs = await self._resolver.resolve(host, port, family=self._family)
            ^^^^^^^^^^^^^^^^^^^^^^^^^^^^^^^^^^^^^^^^^^^^^^^^^^^^^^^^^^^^^
  File "D:\disscord_bots\music\.venv\Lib\site-packages\aiohttp\resolver.py", line 33, in resolve
    infos = await self._loop.getaddrinfo(
            ^^^^^^^^^^^^^^^^^^^^^^^^^^^^^
  File "C:\Users\Lenovo\AppData\Local\Programs\Python\Python311\Lib\asyncio\base_events.py", line 867, in getaddrinfo
    return await self.run_in_executor(
           ^^^^^^^^^^^^^^^^^^^^^^^^^^^
  File "C:\Users\Lenovo\AppData\Local\Programs\Python\Python311\Lib\concurrent\futures\thread.py", line 58, in run
    result = self.fn(*self.args, **self.kwargs)
             ^^^^^^^^^^^^^^^^^^^^^^^^^^^^^^^^^^
  File "C:\Users\Lenovo\AppData\Local\Programs\Python\Python311\Lib\socket.py", line 962, in getaddrinfo
    for res in _socket.getaddrinfo(host, port, family, type, proto, flags):
               ^^^^^^^^^^^^^^^^^^^^^^^^^^^^^^^^^^^^^^^^^^^^^^^^^^^^^^^^^^^
socket.gaierror: [Errno 11001] getaddrinfo failed

The above exception was the direct cause of the following exception:

Traceback (most recent call last):
  File "D:\disscord_bots\music\.venv\Lib\site-packages\discord\client.py", line 597, in connect
    self.ws = await asyncio.wait_for(coro, timeout=60.0)
              ^^^^^^^^^^^^^^^^^^^^^^^^^^^^^^^^^^^^^^^^^^
  File "C:\Users\Lenovo\AppData\Local\Programs\Python\Python311\Lib\asyncio\tasks.py", line 489, in wait_for
    return fut.result()
           ^^^^^^^^^^^^
  File "D:\disscord_bots\music\.venv\Lib\site-packages\discord\gateway.py", line 337, in from_client
    gateway = gateway or await client.http.get_gateway()
                         ^^^^^^^^^^^^^^^^^^^^^^^^^^^^^^^
  File "D:\disscord_bots\music\.venv\Lib\site-packages\discord\http.py", line 2905, in get_gateway
    data = await self.request(Route("GET", "/gateway"))
           ^^^^^^^^^^^^^^^^^^^^^^^^^^^^^^^^^^^^^^^^^^^^
  File "D:\disscord_bots\music\.venv\Lib\site-packages\discord\http.py", line 283, in request
    async with self.__session.request(
  File "D:\disscord_bots\music\.venv\Lib\site-packages\aiohttp\client.py", line 1187, in __aenter__
    self._resp = await self._coro
                 ^^^^^^^^^^^^^^^^
  File "D:\disscord_bots\music\.venv\Lib\site-packages\aiohttp\client.py", line 574, in _request
    conn = await self._connector.connect(
           ^^^^^^^^^^^^^^^^^^^^^^^^^^^^^^
  File "D:\disscord_bots\music\.venv\Lib\site-packages\aiohttp\connector.py", line 544, in connect
    proto = await self._create_connection(req, traces, timeout)
            ^^^^^^^^^^^^^^^^^^^^^^^^^^^^^^^^^^^^^^^^^^^^^^^^^^^
  File "D:\disscord_bots\music\.venv\Lib\site-packages\aiohttp\connector.py", line 911, in _create_connection
    _, proto = await self._create_direct_connection(req, traces, timeout)
               ^^^^^^^^^^^^^^^^^^^^^^^^^^^^^^^^^^^^^^^^^^^^^^^^^^^^^^^^^^
  File "D:\disscord_bots\music\.venv\Lib\site-packages\aiohttp\connector.py", line 1187, in _create_direct_connection
    raise ClientConnectorError(req.connection_key, exc) from exc
aiohttp.client_exceptions.ClientConnectorError: Cannot connect to host discord.com:443 ssl:default [getaddrinfo failed]
ERROR      - 2023-12-19 20:42:56,103 - client          : Attempting a reconnect in 10.16s
Traceback (most recent call last):
  File "D:\disscord_bots\music\.venv\Lib\site-packages\aiohttp\connector.py", line 1173, in _create_direct_connection
    hosts = await asyncio.shield(host_resolved)
            ^^^^^^^^^^^^^^^^^^^^^^^^^^^^^^^^^^^
  File "D:\disscord_bots\music\.venv\Lib\site-packages\aiohttp\connector.py", line 884, in _resolve_host
    addrs = await self._resolver.resolve(host, port, family=self._family)
            ^^^^^^^^^^^^^^^^^^^^^^^^^^^^^^^^^^^^^^^^^^^^^^^^^^^^^^^^^^^^^
  File "D:\disscord_bots\music\.venv\Lib\site-packages\aiohttp\resolver.py", line 33, in resolve
    infos = await self._loop.getaddrinfo(
            ^^^^^^^^^^^^^^^^^^^^^^^^^^^^^
  File "C:\Users\Lenovo\AppData\Local\Programs\Python\Python311\Lib\asyncio\base_events.py", line 867, in getaddrinfo
    return await self.run_in_executor(
           ^^^^^^^^^^^^^^^^^^^^^^^^^^^
  File "C:\Users\Lenovo\AppData\Local\Programs\Python\Python311\Lib\concurrent\futures\thread.py", line 58, in run
    result = self.fn(*self.args, **self.kwargs)
             ^^^^^^^^^^^^^^^^^^^^^^^^^^^^^^^^^^
  File "C:\Users\Lenovo\AppData\Local\Programs\Python\Python311\Lib\socket.py", line 962, in getaddrinfo
    for res in _socket.getaddrinfo(host, port, family, type, proto, flags):
               ^^^^^^^^^^^^^^^^^^^^^^^^^^^^^^^^^^^^^^^^^^^^^^^^^^^^^^^^^^^
socket.gaierror: [Errno 11001] getaddrinfo failed

The above exception was the direct cause of the following exception:

Traceback (most recent call last):
  File "D:\disscord_bots\music\.venv\Lib\site-packages\discord\client.py", line 597, in connect
    self.ws = await asyncio.wait_for(coro, timeout=60.0)
              ^^^^^^^^^^^^^^^^^^^^^^^^^^^^^^^^^^^^^^^^^^
  File "C:\Users\Lenovo\AppData\Local\Programs\Python\Python311\Lib\asyncio\tasks.py", line 489, in wait_for
    return fut.result()
           ^^^^^^^^^^^^
  File "D:\disscord_bots\music\.venv\Lib\site-packages\discord\gateway.py", line 337, in from_client
    gateway = gateway or await client.http.get_gateway()
                         ^^^^^^^^^^^^^^^^^^^^^^^^^^^^^^^
  File "D:\disscord_bots\music\.venv\Lib\site-packages\discord\http.py", line 2905, in get_gateway
    data = await self.request(Route("GET", "/gateway"))
           ^^^^^^^^^^^^^^^^^^^^^^^^^^^^^^^^^^^^^^^^^^^^
  File "D:\disscord_bots\music\.venv\Lib\site-packages\discord\http.py", line 283, in request
    async with self.__session.request(
  File "D:\disscord_bots\music\.venv\Lib\site-packages\aiohttp\client.py", line 1187, in __aenter__
    self._resp = await self._coro
                 ^^^^^^^^^^^^^^^^
  File "D:\disscord_bots\music\.venv\Lib\site-packages\aiohttp\client.py", line 574, in _request
    conn = await self._connector.connect(
           ^^^^^^^^^^^^^^^^^^^^^^^^^^^^^^
  File "D:\disscord_bots\music\.venv\Lib\site-packages\aiohttp\connector.py", line 544, in connect
    proto = await self._create_connection(req, traces, timeout)
            ^^^^^^^^^^^^^^^^^^^^^^^^^^^^^^^^^^^^^^^^^^^^^^^^^^^
  File "D:\disscord_bots\music\.venv\Lib\site-packages\aiohttp\connector.py", line 911, in _create_connection
    _, proto = await self._create_direct_connection(req, traces, timeout)
               ^^^^^^^^^^^^^^^^^^^^^^^^^^^^^^^^^^^^^^^^^^^^^^^^^^^^^^^^^^
  File "D:\disscord_bots\music\.venv\Lib\site-packages\aiohttp\connector.py", line 1187, in _create_direct_connection
    raise ClientConnectorError(req.connection_key, exc) from exc
aiohttp.client_exceptions.ClientConnectorError: Cannot connect to host discord.com:443 ssl:default [getaddrinfo failed]
ERROR      - 2023-12-19 20:43:06,309 - client          : Attempting a reconnect in 18.12s
Traceback (most recent call last):
  File "D:\disscord_bots\music\.venv\Lib\site-packages\aiohttp\connector.py", line 1173, in _create_direct_connection
    hosts = await asyncio.shield(host_resolved)
            ^^^^^^^^^^^^^^^^^^^^^^^^^^^^^^^^^^^
  File "D:\disscord_bots\music\.venv\Lib\site-packages\aiohttp\connector.py", line 884, in _resolve_host
    addrs = await self._resolver.resolve(host, port, family=self._family)
            ^^^^^^^^^^^^^^^^^^^^^^^^^^^^^^^^^^^^^^^^^^^^^^^^^^^^^^^^^^^^^
  File "D:\disscord_bots\music\.venv\Lib\site-packages\aiohttp\resolver.py", line 33, in resolve
    infos = await self._loop.getaddrinfo(
            ^^^^^^^^^^^^^^^^^^^^^^^^^^^^^
  File "C:\Users\Lenovo\AppData\Local\Programs\Python\Python311\Lib\asyncio\base_events.py", line 867, in getaddrinfo
    return await self.run_in_executor(
           ^^^^^^^^^^^^^^^^^^^^^^^^^^^
  File "C:\Users\Lenovo\AppData\Local\Programs\Python\Python311\Lib\concurrent\futures\thread.py", line 58, in run
    result = self.fn(*self.args, **self.kwargs)
             ^^^^^^^^^^^^^^^^^^^^^^^^^^^^^^^^^^
  File "C:\Users\Lenovo\AppData\Local\Programs\Python\Python311\Lib\socket.py", line 962, in getaddrinfo
    for res in _socket.getaddrinfo(host, port, family, type, proto, flags):
               ^^^^^^^^^^^^^^^^^^^^^^^^^^^^^^^^^^^^^^^^^^^^^^^^^^^^^^^^^^^
socket.gaierror: [Errno 11001] getaddrinfo failed

The above exception was the direct cause of the following exception:

Traceback (most recent call last):
  File "D:\disscord_bots\music\.venv\Lib\site-packages\discord\client.py", line 597, in connect
    self.ws = await asyncio.wait_for(coro, timeout=60.0)
              ^^^^^^^^^^^^^^^^^^^^^^^^^^^^^^^^^^^^^^^^^^
  File "C:\Users\Lenovo\AppData\Local\Programs\Python\Python311\Lib\asyncio\tasks.py", line 489, in wait_for
    return fut.result()
           ^^^^^^^^^^^^
  File "D:\disscord_bots\music\.venv\Lib\site-packages\discord\gateway.py", line 337, in from_client
    gateway = gateway or await client.http.get_gateway()
                         ^^^^^^^^^^^^^^^^^^^^^^^^^^^^^^^
  File "D:\disscord_bots\music\.venv\Lib\site-packages\discord\http.py", line 2905, in get_gateway
    data = await self.request(Route("GET", "/gateway"))
           ^^^^^^^^^^^^^^^^^^^^^^^^^^^^^^^^^^^^^^^^^^^^
  File "D:\disscord_bots\music\.venv\Lib\site-packages\discord\http.py", line 283, in request
    async with self.__session.request(
  File "D:\disscord_bots\music\.venv\Lib\site-packages\aiohttp\client.py", line 1187, in __aenter__
    self._resp = await self._coro
                 ^^^^^^^^^^^^^^^^
  File "D:\disscord_bots\music\.venv\Lib\site-packages\aiohttp\client.py", line 574, in _request
    conn = await self._connector.connect(
           ^^^^^^^^^^^^^^^^^^^^^^^^^^^^^^
  File "D:\disscord_bots\music\.venv\Lib\site-packages\aiohttp\connector.py", line 544, in connect
    proto = await self._create_connection(req, traces, timeout)
            ^^^^^^^^^^^^^^^^^^^^^^^^^^^^^^^^^^^^^^^^^^^^^^^^^^^
  File "D:\disscord_bots\music\.venv\Lib\site-packages\aiohttp\connector.py", line 911, in _create_connection
    _, proto = await self._create_direct_connection(req, traces, timeout)
               ^^^^^^^^^^^^^^^^^^^^^^^^^^^^^^^^^^^^^^^^^^^^^^^^^^^^^^^^^^
  File "D:\disscord_bots\music\.venv\Lib\site-packages\aiohttp\connector.py", line 1187, in _create_direct_connection
    raise ClientConnectorError(req.connection_key, exc) from exc
aiohttp.client_exceptions.ClientConnectorError: Cannot connect to host discord.com:443 ssl:default [getaddrinfo failed]
ERROR      - 2023-12-19 20:43:24,463 - client          : Attempting a reconnect in 26.82s
Traceback (most recent call last):
  File "D:\disscord_bots\music\.venv\Lib\site-packages\aiohttp\connector.py", line 1173, in _create_direct_connection
    hosts = await asyncio.shield(host_resolved)
            ^^^^^^^^^^^^^^^^^^^^^^^^^^^^^^^^^^^
  File "D:\disscord_bots\music\.venv\Lib\site-packages\aiohttp\connector.py", line 884, in _resolve_host
    addrs = await self._resolver.resolve(host, port, family=self._family)
            ^^^^^^^^^^^^^^^^^^^^^^^^^^^^^^^^^^^^^^^^^^^^^^^^^^^^^^^^^^^^^
  File "D:\disscord_bots\music\.venv\Lib\site-packages\aiohttp\resolver.py", line 33, in resolve
    infos = await self._loop.getaddrinfo(
            ^^^^^^^^^^^^^^^^^^^^^^^^^^^^^
  File "C:\Users\Lenovo\AppData\Local\Programs\Python\Python311\Lib\asyncio\base_events.py", line 867, in getaddrinfo
    return await self.run_in_executor(
           ^^^^^^^^^^^^^^^^^^^^^^^^^^^
  File "C:\Users\Lenovo\AppData\Local\Programs\Python\Python311\Lib\concurrent\futures\thread.py", line 58, in run
    result = self.fn(*self.args, **self.kwargs)
             ^^^^^^^^^^^^^^^^^^^^^^^^^^^^^^^^^^
  File "C:\Users\Lenovo\AppData\Local\Programs\Python\Python311\Lib\socket.py", line 962, in getaddrinfo
    for res in _socket.getaddrinfo(host, port, family, type, proto, flags):
               ^^^^^^^^^^^^^^^^^^^^^^^^^^^^^^^^^^^^^^^^^^^^^^^^^^^^^^^^^^^
socket.gaierror: [Errno 11001] getaddrinfo failed

The above exception was the direct cause of the following exception:

Traceback (most recent call last):
  File "D:\disscord_bots\music\.venv\Lib\site-packages\discord\client.py", line 597, in connect
    self.ws = await asyncio.wait_for(coro, timeout=60.0)
              ^^^^^^^^^^^^^^^^^^^^^^^^^^^^^^^^^^^^^^^^^^
  File "C:\Users\Lenovo\AppData\Local\Programs\Python\Python311\Lib\asyncio\tasks.py", line 489, in wait_for
    return fut.result()
           ^^^^^^^^^^^^
  File "D:\disscord_bots\music\.venv\Lib\site-packages\discord\gateway.py", line 337, in from_client
    gateway = gateway or await client.http.get_gateway()
                         ^^^^^^^^^^^^^^^^^^^^^^^^^^^^^^^
  File "D:\disscord_bots\music\.venv\Lib\site-packages\discord\http.py", line 2905, in get_gateway
    data = await self.request(Route("GET", "/gateway"))
           ^^^^^^^^^^^^^^^^^^^^^^^^^^^^^^^^^^^^^^^^^^^^
  File "D:\disscord_bots\music\.venv\Lib\site-packages\discord\http.py", line 283, in request
    async with self.__session.request(
  File "D:\disscord_bots\music\.venv\Lib\site-packages\aiohttp\client.py", line 1187, in __aenter__
    self._resp = await self._coro
                 ^^^^^^^^^^^^^^^^
  File "D:\disscord_bots\music\.venv\Lib\site-packages\aiohttp\client.py", line 574, in _request
    conn = await self._connector.connect(
           ^^^^^^^^^^^^^^^^^^^^^^^^^^^^^^
  File "D:\disscord_bots\music\.venv\Lib\site-packages\aiohttp\connector.py", line 544, in connect
    proto = await self._create_connection(req, traces, timeout)
            ^^^^^^^^^^^^^^^^^^^^^^^^^^^^^^^^^^^^^^^^^^^^^^^^^^^
  File "D:\disscord_bots\music\.venv\Lib\site-packages\aiohttp\connector.py", line 911, in _create_connection
    _, proto = await self._create_direct_connection(req, traces, timeout)
               ^^^^^^^^^^^^^^^^^^^^^^^^^^^^^^^^^^^^^^^^^^^^^^^^^^^^^^^^^^
  File "D:\disscord_bots\music\.venv\Lib\site-packages\aiohttp\connector.py", line 1187, in _create_direct_connection
    raise ClientConnectorError(req.connection_key, exc) from exc
aiohttp.client_exceptions.ClientConnectorError: Cannot connect to host discord.com:443 ssl:default [getaddrinfo failed]
INFO       - 2023-12-19 20:43:33,753 - voice_client    : The voice handshake is being terminated for Channel ID 1185958109823381597 (Guild ID 1185958109353615501)
INFO       - 2023-12-19 20:43:51,977 - gateway         : Shard ID None has sent the RESUME payload.
INFO       - 2023-12-19 20:43:52,300 - gateway         : Shard ID None session has been invalidated.
INFO       - 2023-12-19 20:43:52,613 - client          : Got a request to IDENTIFY the websocket.
INFO       - 2023-12-19 20:43:58,169 - gateway         : Shard ID None has sent the IDENTIFY payload.
INFO       - 2023-12-19 20:43:58,582 - gateway         : Shard ID None has connected to Gateway: ["gateway-prd-us-east1-c-45f3",{"micros":74531,"calls":["id_created",{"micros":1841,"calls":[]},"session_lookup_time",{"micros":472,"calls":[]},"session_lookup_finished",{"micros":14,"calls":[]},"discord-sessions-prd-2-68",{"micros":71598,"calls":["start_session",{"micros":48700,"calls":["discord-api-dc69f8484-8qhj2",{"micros":43249,"calls":["get_user",{"micros":9592},"get_guilds",{"micros":4209},"send_scheduled_deletion_message",{"micros":11},"guild_join_requests",{"micros":2},"authorized_ip_coro",{"micros":10}]}]},"starting_guild_connect",{"micros":60,"calls":[]},"presence_started",{"micros":10016,"calls":[]},"guilds_started",{"micros":160,"calls":[]},"guilds_connect",{"micros":2,"calls":[]},"presence_connect",{"micros":12630,"calls":[]},"connect_finished",{"micros":12635,"calls":[]},"build_ready",{"micros":23,"calls":[]},"clean_ready",{"micros":2,"calls":[]},"optimize_ready",{"micros":0,"calls":[]},"split_ready",{"micros":1,"calls":[]}]}]}] (Session ID: 1d6ba291ab1c2dfc6b64555ac01c80a9).
INFO       - 2023-12-19 20:46:14,114 - client          : Received signal to terminate bot and event loop.
INFO       - 2023-12-19 20:46:14,115 - client          : Cleaning up tasks.
INFO       - 2023-12-19 20:46:14,115 - client          : Cleaning up after 3 tasks.
INFO       - 2023-12-19 20:46:14,120 - client          : All tasks finished cancelling.
INFO       - 2023-12-19 20:46:14,122 - client          : Closing the event loop.
